<?xml version="1.0" encoding="utf-8"?>

<!-- Created by Amirpooya Shirazi -->

<robot name="IRB6620_R1">

<!-- BASE LINK -->
    <link name="base_link">
        <visual>
            <origin xyz="0 0 0" rpy="0 0 0" />
            <geometry>
                <mesh filename="/home/apshirazi/Isaac_sim_ws/meshes/visual/base_link.stl" />
            </geometry>
            <material name="">
                <color rgba="1 1 1 1" />
            </material>
        </visual>
        <collision>
            <origin xyz="0 0 0" rpy="0 0 0" />
            <geometry>
                <mesh filename="/home/apshirazi/Isaac_sim_ws/meshes/collision/base_link_mod.stl" />
            </geometry>
        </collision>
    </link>

<!-- ROBOT 1 BASE PLATE -->
    <link name="rob1_plate">
        <visual>
            <origin xyz="0 0 0" rpy="0 0 0" />
            <geometry>
            <box size="1 1 0.025"/>
            </geometry>      
            <material name="">
                <color rgba="0 0 0 1" />
            </material>
        </visual>
        <collision>
            <origin xyz="0 0 0" rpy="0 0 0" />
            <geometry>
            <box size="1 1 0.025"/>
            </geometry>
        </collision>
    </link>
    <!-- ROBOT 1 BASE PLATE TO BASE LINK -->
    <joint name="base_rob1_plate" type="fixed">
        <origin xyz="0 0 -0.0125" rpy="0 0 0" />
        <parent link="base_link" />
        <child link="rob1_plate" />
        <axis xyz="0 0 0" />
    </joint>

<!-- ROBOT 1 LINK 1 -->
    <link name="Link_1">
        <visual>
            <origin xyz="0 0 0" rpy="0 0 0" />
            <geometry>
                <mesh filename="/home/apshirazi/Isaac_sim_ws/meshes/visual/Link_1.stl" />
            </geometry>
            <material name="">
                <color rgba="1 1 1 1" />
            </material>
        </visual>
        <collision>
            <origin xyz="0 0 0" rpy="0 0 0" />
            <geometry>
            <mesh filename="/home/apshirazi/Isaac_sim_ws/meshes/collision/Link_1_mod.stl" />
            </geometry>
        </collision>
    </link>
    <!-- ROBOT 1 LINK 1 TO BASE LINK -->
    <joint name="Joint_1" type="revolute">
        <origin xyz="0 0 0.2135" rpy="0 0 0" />
        <parent link="base_link" />
        <child link="Link_1" />
        <axis xyz="0 0 1" />
        <limit effort="10000" lower="-2.967" upper="2.967" velocity="1.745" />
    </joint>

<!-- ROBOT 1 LINK 2 -->
    <link name="Link_2">
        <visual>
            <origin xyz="0 0 0" rpy="0 0 0" />
            <geometry>
                <mesh filename="/home/apshirazi/Isaac_sim_ws/meshes/visual/Link_2.stl" />
            </geometry>
            <material name="">
                <color rgba="1 1 1 1" />
            </material>
        </visual>
        <collision>
            <origin xyz="0 0 0" rpy="0 0 0" />
            <geometry>
                <mesh filename="/home/apshirazi/Isaac_sim_ws/meshes/collision/Link_2_mod.stl" />
            </geometry>
        </collision>
    </link>
    <!-- ROBOT 1 LINK 2 TO LINK 1 -->
    <joint name="Joint_2" type="revolute">
        <origin xyz="0.32 -0.066026 0.4665" rpy="0 0 0" />
        <parent link="Link_1" />
        <child link="Link_2" />
        <axis xyz="0 1 0" />
        <limit effort="10000" lower="-1.134" upper="1.134" velocity="1.57" />
    </joint>

<!-- ROBOT 1 LINK 3 -->
    <link name="Link_3">
        <visual>
            <origin xyz="0 0 0" rpy="0 0 0" />
            <geometry>
                <mesh filename="/home/apshirazi/Isaac_sim_ws/meshes/visual/Link_3.stl" />
            </geometry>
            <material name="">
                <color rgba="1 1 1 1" />
            </material>
        </visual>
        <collision>
            <origin xyz="0 0 0" rpy="0 0 0" />
            <geometry>
                <mesh filename="/home/apshirazi/Isaac_sim_ws/meshes/collision/Link_3_mod.stl" />
            </geometry>
        </collision>
    </link>
    <!-- ROBOT 1 LINK 3 TO LINK 2 -->
    <joint name="Joint_3" type="revolute">
        <origin xyz="0 0 0.975" rpy="0 0 0" />
        <parent link="Link_2" />
        <child link="Link_3" />
        <axis xyz="0 1 0" />
        <limit effort="10000" lower="-3.141" upper="1.221" velocity="1.57" />
    </joint>

<!-- ROBOT 1 LINK 4 -->
    <link name="Link_4">
        <visual>
            <origin xyz="0 0 0" rpy="0 0 0" />
            <geometry>
                <mesh filename="/home/apshirazi/Isaac_sim_ws/meshes/visual/Link_4.stl" />
            </geometry>
            <material name="">
                <color rgba="1 1 1 1" />
            </material>
        </visual>
        <collision>
            <origin xyz="0 0 0" rpy="0 0 0" />
            <geometry>
                <mesh filename="/home/apshirazi/Isaac_sim_ws/meshes/collision/Link_4_mod.stl" />
            </geometry>
        </collision>
    </link>
    <!-- ROBOT 1 LINK 4 TO LINK 3 -->
    <joint name="Joint_4" type="revolute">
        <origin xyz="0.18199387543951 0.0660260255572537 0.2" rpy="0 0 0" />
        <parent link="Link_3" />
        <child link="Link_4" />
        <axis xyz="1 0 0" />
        <limit effort="10000" lower="-5.235" upper="5.235" velocity="2.617" />
    </joint>

<!-- ROBOT 1 LINK 5 -->
    <link name="Link_5">
        <visual>
            <origin xyz="0 0 0" rpy="0 0 0" />
            <geometry>
                <mesh filename="/home/apshirazi/Isaac_sim_ws/meshes/visual/Link_5.stl" />
            </geometry>
            <material name="">
                <color rgba="1 1 1 1" />
            </material>
        </visual>
        <collision>
            <origin xyz="0 0 0" rpy="0 0 0" />
            <geometry>
                <mesh filename="/home/apshirazi/Isaac_sim_ws/meshes/collision/Link_5_mod.stl" />
            </geometry>
        </collision>
    </link>
    <!-- ROBOT 1 LINK 5 TO LINK 4 -->
    <joint name="Joint_5" type="revolute">
        <origin xyz="0.705006124560486 0 0" rpy="0 0 0" />
        <parent link="Link_4" />
        <child link="Link_5" />
        <axis xyz="0 1 0" />
        <limit effort="10000" lower="-2.268" upper="2.268" velocity="2.095" />
    </joint>

<!-- ROBOT 1 LINK 6 -->
    <link name="Link_6">
        <visual>
            <origin xyz="0 0 0" rpy="0 0 0" />
            <geometry>
                <mesh filename="/home/apshirazi/Isaac_sim_ws/meshes/visual/Link_6.stl" />
            </geometry>
            <material name="">
                <color rgba="1 1 1 1" />
            </material>
        </visual>
        <collision>
            <origin xyz="0 0 0" rpy="0 0 0" />
            <geometry>
                <mesh filename="/home/apshirazi/Isaac_sim_ws/meshes/collision/Link_6_mod.stl" />
            </geometry>
        </collision>
    </link>
    <!-- ROBOT 1 LINK 6 TO LINK 5 -->
    <joint name="Joint_6" type="revolute">
        <origin xyz="0.162695495363849 0 0" rpy="0 0 0" />
        <parent link="Link_5" />
        <child link="Link_6" />
        <axis xyz="1 0 0" />
        <limit effort="10000" lower="-5.235" upper="5.235" velocity="3.316" />
    </joint>

<!-- ROBOT 1 ENDEFFECTOR -->
    <link name="Link_7">
        <visual>
            <origin xyz="0 0 0" rpy="0 0 0" />
            <geometry>
                <mesh filename="/home/apshirazi/Isaac_sim_ws/meshes/visual/Link_7.stl">
                </mesh>
            </geometry>
            <material name="">
                <color rgba="0 0 1 1" />
            </material>
        </visual>
        <collision>
            <origin xyz="0 0 0" rpy="0 0 0" />
            <geometry>
                <mesh filename="/home/apshirazi/Isaac_sim_ws/meshes/collision/Link_7.stl">
                </mesh>
            </geometry>
        </collision>
    </link>
    <!-- ROBOT 1 ENDEFFECTOR TO LINK 6 -->
    <joint name="Joint_7" type="fixed">
        <origin xyz="0.05 0 0" rpy="0 1.5707963267949 0" />
        <parent link="Link_6" />
        <child link="Link_7" />
        <axis xyz="0 0 0" />
    </joint>
<!-- ROBOT 1 NAILER -->
    <link name="Link_8">
        <visual>
            <origin xyz="0 0 0" rpy="0 0 0" />
            <geometry>
                <mesh filename="/home/apshirazi/Isaac_sim_ws/meshes/visual/Link_8.stl" />
            </geometry>
            <material name="">
                <color rgba="0 1 0 1" />
            </material>
        </visual>
        <collision>
            <origin xyz="0 0 0" rpy="0 0 0" />
            <geometry>
                <mesh filename="/home/apshirazi/Isaac_sim_ws/meshes/collision/Link_8.stl" />
            </geometry>
        </collision>
    </link>
    <!-- ROBOT 1 NAILER TO ENDEFFECTOR -->
    <joint name="Joint_8" type="revolute">
        <origin xyz="0.0710604735167422 -0.4640008 0.0758673046361571" rpy="0 0 0" />
        <parent link="Link_7" />
        <child link="Link_8" />
        <axis xyz="1 0 0" />
        <limit effort="10000" lower="0" upper="1.57" velocity="10.0" />
    </joint>

    <!-- base_link -->
    <link name="base" />
    <joint name="base_link-base" type="fixed">
        <origin xyz="0 0 0" rpy="0 0 0"/>
        <parent link="base_link"/>
        <child link="base"/>
    </joint>

    <!-- flange frame -->
    <link name="flange"/>
    <joint type="fixed" name="joint_6-flange">
        <origin xyz="0 0 0" rpy="0 0 0"/>
        <parent link="Link_6"/>
        <child link="flange"/>
        <child link="Link_7"/>
    </joint>

    <!-- EF1_GR tool frame -->
    <link name="tool0" />
    <joint name="Link_6-tool0" type="fixed">
        <origin xyz="0.087264505 0.0 -0.24" rpy="-3.1415927 0 0" />
        <parent link="flange" />
        <child link="tool0" />
    </joint>

    <!-- EF1_SC tool frame -->
    <link name="tool1" />
    <joint name="Link_6-tool1" type="fixed">
        <origin xyz="0.502065 0.43505 -0.176663" rpy="-1.57079632679 0.0 -1.57079632679" />
        <parent link="flange" />
        <child link="tool1" />
    </joint>

    <!-- EF1_NG tool frame -->
    <link name="tool2" />
    <joint name="flange-tool2" type="fixed">
        <origin xyz="0.400 -0.327 0.0" rpy="-1.57079632679 0 -1.57079632679" />
        <parent link="flange" />
        <child link="tool2" />
    </joint>

    <!-- EF1_NG2 tool frame -->
    <link name="tool3" />
    <joint name="Link_6-tool3" type="fixed">
        <origin xyz="0.226962 -0.705 0.002537" rpy="-1.57079632679 0.174533 0" />
        <parent link="flange" />
        <child link="tool3" />
    </joint>

    <!-- Creating Surface Gripper Xforms for Isaac Sim Surface Gripper Extension (Attach/Detach) -->
    <!-- <link name="GripPosition_T1_X">
    <joint name="GT1X_To_L7" type="fixed">
        <origin xyz="0 0 0" rpy="0 0 0"/>
        <parent link="Link_7">
        <child link="GripPosition_T1_X"/>
    </joint> -->
   
</robot>