<?xml version="1.0" encoding="utf-8"?>
<!-- This URDF was automatically created by SolidWorks to URDF Exporter! Originally created by Stephen Brawner (brawner@gmail.com) 
     Commit Version: 1.6.0-4-g7f85cfe  Build Version: 1.6.7995.38578
     For more information, please see http://wiki.ros.org/sw_urdf_exporter -->
<robot
  name="idc_lab">
  <link
    name="base_link">
    <visual>
      <origin
        xyz="0 0 0"
        rpy="0 0 0" />
      <geometry>
        <mesh
          filename="~/IDC_Lab/src/idc_lab/meshes/visual/base_link.stl" />
      </geometry>
      <material name="">
          <color rgba="1 1 1 1" />
      </material>
    </visual>
    <collision>
      <origin
        xyz="0 0 0"
        rpy="0 0 0" />
      <geometry>
        <mesh
          filename="~/IDC_Lab/src/idc_lab/meshes/collision/base_link_mod.stl" />
      </geometry>
    </collision>
  </link>
  
  <!-- mat_table_tilted -->
  <link
    name="mat_table_tilted">
    <visual>
      <origin
        xyz="0 0 0"
        rpy="0 0 0" />
      <geometry>
        <mesh
          filename="~/IDC_Lab/src/idc_lab/meshes/visual/MatTable_tilted.stl" scale="0.001 0.001 0.001"/>
      </geometry>    
      <material
        name="">
        <color
          rgba="0.45098039215686275 0.5215686274509804 0.5843137254901961 1.0" />
      </material>   
    </visual>
    <collision>
      <origin
        xyz="0 0 0"
        rpy="0 0 0" />
      <geometry>
        <mesh
          filename="~/IDC_Lab/src/idc_lab/meshes/collision/MatTable_tilted.stl" scale="0.001 0.001 0.001"/>
      </geometry>
    </collision>
  </link>
  <joint
    name="base_to_mat_table_tilted"
    type="fixed">
    <origin
      xyz="0 0 -0.05"
      rpy="0 0 0" />
    <parent
      link="base_link" />
    <child
      link="mat_table_tilted" />
    <axis
      xyz="0 0 0" />
  </joint>

  <!-- mat_table_6_level -->
  <link
    name="mat_table_6_level">
    <visual>
      <origin
        xyz="0 0 0"
        rpy="0 0 0" />
      <geometry>
        <mesh
          filename="~/IDC_Lab/src/idc_lab/meshes/visual/MatTable_6Level.stl" scale="0.001 0.001 0.001"/>
      </geometry>    
      <material
        name="">
        <color
          rgba="0.45098039215686275 0.5215686274509804 0.5843137254901961 1.0" />
      </material>   
    </visual>
    <collision>
      <origin
        xyz="0 0 0"
        rpy="0 0 0" />
      <geometry>
        <mesh
          filename="~/IDC_Lab/src/idc_lab/meshes/visual/MatTable_6Level.stl" scale="0.001 0.001 0.001"/>
      </geometry>
    </collision>
  </link>
  <joint
    name="base_to_mat_table_6_level"
    type="fixed">
    <origin
      xyz="0 0 -0.05"
      rpy="0 0 0" />
    <parent
      link="base_link" />
    <child
      link="mat_table_6_level" />
    <axis
      xyz="0 0 0" />
  </joint>

    <!-- mat_table_3_level -->
  <link
    name="mat_table_3_level">
    <visual>
      <origin
        xyz="0 0 0"
        rpy="0 0 0" />
      <geometry>
        <mesh
          filename="~/IDC_Lab/src/idc_lab/meshes/visual/MatTable_3Level.stl" scale="0.001 0.001 0.001"/>
      </geometry>    
      <material
        name="">
        <color
          rgba="0.45098039215686275 0.5215686274509804 0.5843137254901961 1.0" />
      </material>   
    </visual>
    <collision>
      <origin
        xyz="0 0 0"
        rpy="0 0 0" />
      <geometry>
        <mesh
          filename="~/IDC_Lab/src/idc_lab/meshes/visual/MatTable_3Level.stl" scale="0.001 0.001 0.001"/>
      </geometry>
    </collision>
  </link>
  <joint
    name="base_to_mat_table_3_level"
    type="fixed">
    <origin
      xyz="0 0 -0.05"
      rpy="0 0 0" />
    <parent
      link="base_link" />
    <child
      link="mat_table_3_level" />
    <axis
      xyz="0 0 0" />
  </joint>

  <!-- new_convn_1 -->
  <link
    name="new_convn_1">
    <visual>
      <origin
        xyz="0 0 0"
        rpy="0 0 0" />
      <geometry>
        <mesh
          filename="~/IDC_Lab/src/idc_lab/meshes/visual/NewConvn1_V2.stl" scale="0.001 0.001 0.001"/>
      </geometry>    
      <material
        name="">
        <color
          rgba="0.611764705882353 0.42745098039215684 0.3411764705882353 1.0" />
      </material>   
    </visual>
    <collision>
      <origin
        xyz="0 0 0"
        rpy="0 0 0" />
      <geometry>
        <mesh
          filename="~/IDC_Lab/src/idc_lab/meshes/collision/NewConvn1_V2.stl" scale="0.001 0.001 0.001"/>
      </geometry>
    </collision>
  </link>
  <joint
    name="base_to_new_convn_1"
    type="fixed">
    <origin
      xyz="0 0 -0.05"
      rpy="0 0 0" />
    <parent
      link="base_link" />
    <child
      link="new_convn_1" />
    <axis
      xyz="0 0 0" />
  </joint>

  <!-- new_convn_2 -->
  <link
    name="new_convn_2">
    <visual>
      <origin
        xyz="0 0 0"
        rpy="0 0 0" />
      <geometry>
        <mesh
          filename="~/IDC_Lab/src/idc_lab/meshes/visual/NewConvn2_V2.stl" scale="0.001 0.001 0.001"/>
      </geometry>    
      <material
        name="">
        <color
          rgba="0.611764705882353 0.42745098039215684 0.3411764705882353 1.0" />
      </material>   
    </visual>
    <collision>
      <origin
        xyz="0.05 0 0"
        rpy="0 0 0" />
      <geometry>
        <mesh
          filename="~/IDC_Lab/src/idc_lab/meshes/collision/NewConvn2_V2.stl" scale="0.00098 0.001 0.001"/>
      </geometry>
    </collision>
  </link>
  <joint
    name="base_to_new_convn_2"
    type="fixed">
    <origin
      xyz="0 0 -0.05"
      rpy="0 0 0" />
    <parent
      link="base_link" />
    <child
      link="new_convn_2" />
    <axis
      xyz="0 0 0" />
  </joint>

  <!-- new_sheathing_rack -->
  <link
    name="new_sheathing_rack">
    <visual>
      <origin
        xyz="0 0 0"
        rpy="0 0 0" />
      <geometry>
        <mesh
          filename="~/IDC_Lab/src/idc_lab/meshes/visual/NewSheathingRack.stl" scale="0.001 0.001 0.001"/>
      </geometry>    
      <material
        name="">
        <color
          rgba="0.611764705882353 0.42745098039215684 0.3411764705882353 1.0" />
      </material>   
    </visual>
    <collision>
      <origin
        xyz="-2.1 -2.9 0"
        rpy="0 0 0" />
      <geometry>
        <mesh
          filename="~/IDC_Lab/src/idc_lab/meshes/collision/NewSheathingRack.stl" scale="0.00117 0.001 0.0010"/>
      </geometry>
    </collision>
  </link>
  <joint
    name="base_to_new_sheathing_rack"
    type="fixed">
    <origin
      xyz="0 0 -0.05"
      rpy="0 0 0" />
    <parent
      link="base_link" />
    <child
      link="new_sheathing_rack" />
    <axis
      xyz="0 0 0" />
  </joint>

  <!-- FLOOR -->
  <link
    name="floor">

    <collision>
      <origin
        xyz="0 0 0"
        rpy="0 0 0" />
      <geometry>
        <box size="20 20 0.0000001"/>
      </geometry>
    </collision>

    <visual>
        <origin
          xyz="2.3 0 0"
          rpy="0 0 0" />
        <geometry>
        <box size= "20 20 0.0000001"/>
      </geometry>
      <material name="ground_texture">
        <texture filename="~/IDC_Lab/src/idc_lab/textures/concrete2.png"/>
      </material>
    </visual>

  </link>
  <joint
    name="base_floor"
    type="fixed">
    <origin
      xyz="0 0 -0.050"
      rpy="0 0 0" />
    <parent
      link="base_link" />
    <child
      link="floor" />
    <axis
      xyz="0 0 0" />
  </joint>
  
  <!-- ROOF -->
  <link
    name="roof">
    <collision>
      <origin
        xyz="0 0 0"
        rpy="0 0 0" />
      <geometry>
        <box size="20 20 0.01"/>
      </geometry>
    </collision>
  </link>
  <joint
    name="base_roof"
    type="fixed">
    <origin
      xyz="0 0 3.6576"
      rpy="0 0 0" />
    <parent
      link="base_link" />
    <child
      link="roof" />
    <axis
      xyz="0 0 0" />
  </joint>

  <!-- robot 1 base plate -->
  <link
    name="rob1_plate">
    <visual>
      <origin
        xyz="0 0 0"
        rpy="0 0 0" />
      <geometry>
        <box size="1 1 0.025"/>
      </geometry>      
      <material name="">
          <color rgba="0 0 0 1" />
      </material>
    </visual>
    <collision>
      <origin
        xyz="0 0 0"
        rpy="0 0 0" />
      <geometry>
        <box size="1 1 0.025"/>
      </geometry>
    </collision>
  </link>
  <joint
    name="base_rob1_plate"
    type="fixed">
    <origin
      xyz="0 0 -0.0125"
      rpy="0 0 0" />
    <parent
      link="base_link" />
    <child
      link="rob1_plate" />
    <axis
      xyz="0 0 0" />
  </joint>
  
  <!-- robot 1 link 1 -->
  <link
    name="Link_1">
    <visual>
      <origin
        xyz="0 0 0"
        rpy="0 0 0" />
      <geometry>
        <mesh
          filename="~/IDC_Lab/src/idc_lab/meshes/visual/Link_1.stl" />
      </geometry>
      <material name="">
          <color rgba="1 1 1 1" />
      </material>
    </visual>
    <collision>
      <origin
        xyz="0 0 0"
        rpy="0 0 0" />
      <geometry>
        <mesh
          filename="~/IDC_Lab/src/idc_lab/meshes/collision/Link_1_mod.stl" />
      </geometry>
    </collision>
  </link>
  <joint
    name="Joint_1"
    type="revolute">
    <origin
      xyz="0 0 0.2135"
      rpy="0 0 0" />
    <parent
      link="base_link" />
    <child
      link="Link_1" />
    <axis
      xyz="0 0 1" />
    <limit
      effort="0"
      lower="-2.967"
      upper="2.967"
      velocity="1.745" />
  </joint>

  <!-- robot 1 link 2 -->
  <link
    name="Link_2">
    <visual>
      <origin
        xyz="0 0 0"
        rpy="0 0 0" />
      <geometry>
        <mesh
          filename="~/IDC_Lab/src/idc_lab/meshes/visual/Link_2.stl" />
      </geometry>
      <material name="">
          <color rgba="1 1 1 1" />
      </material>
    </visual>
    <collision>
      <origin
        xyz="0 0 0"
        rpy="0 0 0" />
      <geometry>
        <mesh
          filename="~/IDC_Lab/src/idc_lab/meshes/collision/Link_2_mod.stl" />
      </geometry>
    </collision>
  </link>
  <joint
    name="Joint_2"
    type="revolute">
    <origin
      xyz="0.32 -0.066026 0.4665"
      rpy="0 0 0" />
    <parent
      link="Link_1" />
    <child
      link="Link_2" />
    <axis
      xyz="0 1 0" />
    <limit
      effort="0"
      lower="-1.134"
      upper="1.134"
      velocity="1.57" />
  </joint>
  
  <!-- robot 1 link 3 -->
  <link
    name="Link_3">
    <visual>
      <origin
        xyz="0 0 0"
        rpy="0 0 0" />
      <geometry>
        <mesh
          filename="~/IDC_Lab/src/idc_lab/meshes/visual/Link_3.stl" />
      </geometry>
      <material name="">
          <color rgba="1 1 1 1" />
      </material>
    </visual>
    <collision>
      <origin
        xyz="0 0 0"
        rpy="0 0 0" />
      <geometry>
        <mesh
          filename="~/IDC_Lab/src/idc_lab/meshes/collision/Link_3_mod.stl" />
      </geometry>
    </collision>
  </link>
  <joint
    name="Joint_3"
    type="revolute">
    <origin
      xyz="0 0 0.975"
      rpy="0 0 0" />
    <parent
      link="Link_2" />
    <child
      link="Link_3" />
    <axis
      xyz="0 1 0" />
    <limit
      effort="0"
      lower="-3.141"
      upper="1.221"
      velocity="1.57" />
  </joint>
  
  <!-- robot 1 link 4 -->
  <link
    name="Link_4">
    <visual>
      <origin
        xyz="0 0 0"
        rpy="0 0 0" />
      <geometry>
        <mesh
          filename="~/IDC_Lab/src/idc_lab/meshes/visual/Link_4.stl" />
      </geometry>
      <material name="">
          <color rgba="1 1 1 1" />
      </material>
    </visual>
    <collision>
      <origin
        xyz="0 0 0"
        rpy="0 0 0" />
      <geometry>
        <mesh
          filename="~/IDC_Lab/src/idc_lab/meshes/collision/Link_4_mod.stl" />
      </geometry>
    </collision>
  </link>
  <joint
    name="Joint_4"
    type="revolute">
    <origin
      xyz="0.18199387543951 0.0660260255572537 0.2"
      rpy="0 0 0" />
    <parent
      link="Link_3" />
    <child
      link="Link_4" />
    <axis
      xyz="1 0 0" />
    <limit
      effort="0"
      lower="-5.235"
      upper="5.235"
      velocity="2.617" />
  </joint>

  <!-- robot 1 link 5 -->
  <link
    name="Link_5">
    <visual>
      <origin
        xyz="0 0 0"
        rpy="0 0 0" />
      <geometry>
        <mesh
          filename="~/IDC_Lab/src/idc_lab/meshes/visual/Link_5.stl" />
      </geometry>
      <material name="">
          <color rgba="1 1 1 1" />
      </material>
    </visual>
    <collision>
      <origin
        xyz="0 0 0"
        rpy="0 0 0" />
      <geometry>
        <mesh
          filename="~/IDC_Lab/src/idc_lab/meshes/collision/Link_5_mod.stl" />
      </geometry>
    </collision>
  </link>
  <joint
    name="Joint_5"
    type="revolute">
    <origin
      xyz="0.705006124560486 0 0"
      rpy="0 0 0" />
    <parent
      link="Link_4" />
    <child
      link="Link_5" />
    <axis
      xyz="0 1 0" />
    <limit
      effort="0"
      lower="-2.268"
      upper="2.268"
      velocity="2.095" />
  </joint>
  
  <!-- robot 1 link 6 -->
  <link
    name="Link_6">
    <visual>
      <origin
        xyz="0 0 0"
        rpy="0 0 0" />
      <geometry>
        <mesh
          filename="~/IDC_Lab/src/idc_lab/meshes/visual/Link_6.stl" />
      </geometry>
      <material name="">
          <color rgba="1 1 1 1" />
      </material>
    </visual>
    <collision>
      <origin
        xyz="0 0 0"
        rpy="0 0 0" />
      <geometry>
        <mesh
          filename="~/IDC_Lab/src/idc_lab/meshes/collision/Link_6_mod.stl" />
      </geometry>
    </collision>
  </link>
  <joint
    name="Joint_6"
    type="revolute">
    <origin
      xyz="0.162695495363849 0 0"
      rpy="0 0 0" />
    <parent
      link="Link_5" />
    <child
      link="Link_6" />
    <axis
      xyz="1 0 0" />
    <limit
      effort="0"
      lower="-5.235"
      upper="5.235"
      velocity="3.316" />
  </joint>
  
  <!-- robot 1 end effector -->
  <link
    name="Link_7">
    <visual>
      <origin
        xyz="0 0 0"
        rpy="0 0 0" />
      <geometry>
        <mesh
          filename="~/IDC_Lab/src/idc_lab/meshes/visual/Link_7.stl" />
      </geometry>
      <material name="">
          <color rgba="0 0 1 1" />
      </material>
    </visual>
    <collision>
      <origin
        xyz="0 0 0"
        rpy="0 0 0" />
      <geometry>
        <mesh
          filename="~/IDC_Lab/src/idc_lab/meshes/collision/Link_7.stl" />
      </geometry>
    </collision>
  </link>
  <joint
    name="Joint_7"
    type="fixed">
    <origin
      xyz="0.05 0 0"
      rpy="0 1.5707963267949 0" />
    <parent
      link="Link_6" />
    <child
      link="Link_7" />
    <axis
      xyz="0 0 0" />
  </joint>

  <!-- robot 1 nailer -->
  <link
    name="Link_8">
    <visual>
      <origin
        xyz="0 0 0"
        rpy="0 0 0" />
      <geometry>
        <mesh
          filename="~/IDC_Lab/src/idc_lab/meshes/visual/Link_8.stl" />
      </geometry>
      <material name="">
          <color rgba="0 1 0 1" />
      </material>
    </visual>
    <collision>
      <origin
        xyz="0 0 0"
        rpy="0 0 0" />
      <geometry>
        <mesh
          filename="~/IDC_Lab/src/idc_lab/meshes/collision/Link_8.stl" />
      </geometry>
    </collision>
  </link>
  <joint
    name="Joint_8"
    type="revolute">
    <origin
      xyz="0.0710604735167422 -0.4640008 0.0758673046361571"
      rpy="0 0 0" />
    <parent
      link="Link_7" />
    <child
      link="Link_8" />
    <axis
      xyz="1 0 0" />
    <limit
      effort="0"
      lower="0"
      upper="1.57"
      velocity="10.0" />
  </joint>
  
  <!-- robot 2 base plate -->
  <link
    name="rob2_plate">
    <visual>
      <origin
        xyz="0 0 0"
        rpy="0 0 0" />
      <geometry>
        <box size="1 1 0.025"/>
      </geometry>
      <material name="">
          <color rgba="0 0 0 1" />
      </material>
    </visual>
    <collision>
      <origin
        xyz="0 0 0"
        rpy="0 0 0" />
      <geometry>
        <box size="1 1 0.025"/>
      </geometry>
    </collision>
  </link>
  <joint
    name="base_rob2_plate"
    type="fixed">
    <origin
      xyz="4.6 0 -0.0125"
      rpy="0 0 0" />
    <parent
      link="base_link" />
    <child
      link="rob2_plate" />
    <axis
      xyz="0 0 0" />
  </joint>

  <!-- robot 2 base -->
  <link
    name="Link_9">
    <visual>
      <origin
        xyz="0 0 0"
        rpy="0 0 0" />
      <geometry>
        <mesh
          filename="~/IDC_Lab/src/idc_lab/meshes/visual/Link_9.stl" />
      </geometry>
      <material name="">
          <color rgba="1 1 1 1" />
      </material>
    </visual>
    <collision>
      <origin
        xyz="0 0 0"
        rpy="0 0 0" />
      <geometry>
        <mesh
          filename="~/IDC_Lab/src/idc_lab/meshes/collision/Link_9_mod.stl" />
      </geometry>
    </collision>
  </link>
  <joint
    name="Joint_9"
    type="fixed">
    <origin
      xyz="4.6 0 0"
      rpy="0 0 3.1416" />
    <parent
      link="base_link" />
    <child
      link="Link_9" />
    <axis
      xyz="0 0 0" />
  </joint>

  <!-- robot 2 link 1 -->
  <link
    name="Link_10">
    <visual>
      <origin
        xyz="0 0 0"
        rpy="0 0 0" />
      <geometry>
        <mesh
          filename="~/IDC_Lab/src/idc_lab/meshes/visual/Link_10.stl" />
      </geometry>
      <material name="">
          <color rgba="1 1 1 1" />
      </material>
    </visual>
    <collision>
      <origin
        xyz="0 0 0"
        rpy="0 0 0" />
      <geometry>
        <mesh
          filename="~/IDC_Lab/src/idc_lab/meshes/collision/Link_10_mod.stl" />
      </geometry>
    </collision>
  </link>
  <joint
    name="Joint_10"
    type="revolute">
    <origin
      xyz="0 0 0.2135"
      rpy="0 0 0" />
    <parent
      link="Link_9" />
    <child
      link="Link_10" />
    <axis
      xyz="0 0 1" />
    <limit
      effort="0"
      lower="-3.14159265"
      upper="3.14159265"
      velocity="1.745" />
  </joint>

  <!-- robot 2 link 2 -->
  <link
    name="Link_11">
    <visual>
      <origin
        xyz="0 0 0"
        rpy="0 0 0" />
      <geometry>
        <mesh
          filename="~/IDC_Lab/src/idc_lab/meshes/visual/Link_11.stl" />
      </geometry>
      <material name="">
          <color rgba="1 1 1 1" />
      </material>
    </visual>
    <collision>
      <origin
        xyz="0 0 0"
        rpy="0 0 0" />
      <geometry>
        <mesh
          filename="~/IDC_Lab/src/idc_lab/meshes/collision/Link_11_mod.stl" />
      </geometry>
    </collision>
  </link>
  <joint
    name="Joint_11"
    type="revolute">
    <origin
      xyz="0.32 -0.066026 0.4665"
      rpy="0 0 0" />
    <parent
      link="Link_10" />
    <child
      link="Link_11" />
    <axis
      xyz="0 1 0" />
    <limit
      effort="0"
      lower="-1.134"
      upper="1.134"
      velocity="1.57" />
  </joint>

  <!-- robot 2 link 3 -->
  <link
    name="Link_12">
    <visual>
      <origin
        xyz="0 0 0"
        rpy="0 0 0" />
      <geometry>
        <mesh
          filename="~/IDC_Lab/src/idc_lab/meshes/visual/Link_12.stl" />
      </geometry>
      <material name="">
          <color rgba="1 1 1 1" />
      </material>
    </visual>
    <collision>
      <origin
        xyz="0 0 0"
        rpy="0 0 0" />
      <geometry>
        <mesh
          filename="~/IDC_Lab/src/idc_lab/meshes/collision/Link_12_mod.stl" />
      </geometry>
    </collision>
  </link>
  <joint
    name="Joint_12"
    type="revolute">
    <origin
      xyz="0 0 0.975"
      rpy="0 0 0" />
    <parent
      link="Link_11" />
    <child
      link="Link_12" />
    <axis
      xyz="0 1 0" />
    <limit
      effort="0"
      lower="-3.141"
      upper="1.221"
      velocity="1.57" />
  </joint>

  <!-- robot 2 link 4 -->
  <link
    name="Link_13">
    <visual>
      <origin
        xyz="0 0 0"
        rpy="0 0 0" />
      <geometry>
        <mesh
          filename="~/IDC_Lab/src/idc_lab/meshes/visual/Link_13.stl" />
      </geometry>
      <material name="">
          <color rgba="1 1 1 1" />
      </material>
    </visual>
    <collision>
      <origin
        xyz="0 0 0"
        rpy="0 0 0" />
      <geometry>
        <mesh
          filename="~/IDC_Lab/src/idc_lab/meshes/collision/Link_13_mod.stl" />
      </geometry>
    </collision>
  </link>
  <joint
    name="Joint_13"
    type="revolute">
    <origin
      xyz="0.18199 0.066026 0.2"
      rpy="0 0 0" />
    <parent
      link="Link_12" />
    <child
      link="Link_13" />
    <axis
      xyz="1 0 0" />
    <limit
      effort="0"
      lower="-5.235"
      upper="5.235"
      velocity="2.617" />
  </joint>

  <!-- robot 2 link 5 -->
  <link
    name="Link_14">
    <visual>
      <origin
        xyz="0 0 0"
        rpy="0 0 0" />
      <geometry>
        <mesh
          filename="~/IDC_Lab/src/idc_lab/meshes/visual/Link_14.stl" />
      </geometry>
      <material name="">
          <color rgba="1 1 1 1" />
      </material>
    </visual>
    <collision>
      <origin
        xyz="0 0 0"
        rpy="0 0 0" />
      <geometry>
        <mesh
          filename="~/IDC_Lab/src/idc_lab/meshes/collision/Link_14_mod.stl" />
      </geometry>
    </collision>
  </link>
  <joint
    name="Joint_14"
    type="revolute">
    <origin
      xyz="0.70501 0 0"
      rpy="0 0 0" />
    <parent
      link="Link_13" />
    <child
      link="Link_14" />
    <axis
      xyz="0 1 0" />
    <limit
      effort="0"
      lower="-2.268"
      upper="2.268"
      velocity="2.095" />
  </joint>

  <!-- robot 2 link 6 -->
  <link
    name="Link_15">
    <visual>
      <origin
        xyz="0 0 0"
        rpy="0 0 0" />
      <geometry>
        <mesh
          filename="~/IDC_Lab/src/idc_lab/meshes/visual/Link_15.stl" />
      </geometry>
      <material name="">
          <color rgba="1 1 1 1" />
      </material>
    </visual>
    <collision>
      <origin
        xyz="0 0 0"
        rpy="0 0 0" />
      <geometry>
        <mesh
          filename="~/IDC_Lab/src/idc_lab/meshes/collision/Link_15_mod.stl" />
      </geometry>
    </collision>
  </link>
  <joint
    name="Joint_15"
    type="revolute">
    <origin
      xyz="0.1627 0 0"
      rpy="0 0 0" />
    <parent
      link="Link_14" />
    <child
      link="Link_15" />
    <axis
      xyz="1 0 0" />
    <limit
      effort="0"
      lower="-5.235"
      upper="5.235"
      velocity="3.316" />
  </joint>

  <!-- robot 2 end effector -->
  <link
    name="Link_16">
    <visual>
      <origin
        xyz="0 0 0"
        rpy="0 0 0" />
      <geometry>
        <mesh
          filename="~/IDC_Lab/src/idc_lab/meshes/visual/Link_16.stl" />
      </geometry>
      <material name="">
          <color rgba="0 0 1 1" />
      </material>
    </visual>
    <collision>
      <origin
        xyz="0 0 0"
        rpy="0 0 0" />
      <geometry>
        <mesh
          filename="~/IDC_Lab/src/idc_lab/meshes/collision/Link_16.stl" />
      </geometry>
    </collision>
  </link>
  <joint
    name="Joint_16"
    type="fixed">
    <origin
      xyz="0.05 0 0"
      rpy="3.14 1.5708 0" />
    <parent
      link="Link_15" />
    <child
      link="Link_16" />
    <axis
      xyz="0 0 0" />
  </joint>

  <!-- robot 2 nailer -->
  <link
    name="Link_17">
    <visual>
      <origin
        xyz="0 0 0"
        rpy="0 0 0" />
      <geometry>
        <mesh
          filename="~/IDC_Lab/src/idc_lab/meshes/visual/Link_17.stl" />
      </geometry>
      <material name="">
          <color rgba="0 1 0 1" />
      </material>
    </visual>
    <collision>
      <origin
        xyz="0 0 0"
        rpy="0 0 0" />
      <geometry>
        <mesh
          filename="~/IDC_Lab/src/idc_lab/meshes/collision/Link_17.stl" />
      </geometry>
    </collision>
  </link>
  <joint
    name="Joint_17"
    type="revolute">
    <origin
      xyz="0.071626 0.47938 -0.063969"
      rpy="0 0 0" />
    <parent
      link="Link_16" />
    <child
      link="Link_17" />
    <axis
      xyz="1 0 0" />
    <limit
      effort="0"
      lower="0"
      upper="1.5708"
      velocity="10.0" />
  </joint>
  
  <!-- Framing Conveyor -->
  <link
    name="Link_18">
    <collision>
      <origin
        xyz="0 0 0"
        rpy="0 0 0" />
      <geometry>
        <box size="0.00001 0.000001 0.000001"/>
      </geometry>  
    </collision>
  </link>
  <joint
    name="Joint_18"
    type="prismatic">
    <origin
      xyz="2.0 0.0 -0.3"
      rpy="0 0 0" />
    <parent
      link="base_link" />
    <child
      link="Link_18" />
    <axis
      xyz="0 -1 0" />
    <limit
      effort="100"
      lower="-1000"
      upper="1000"
      velocity="10" />
  </joint>
  
  <!-- Material Conveyor -->
  <link
    name="Link_19">
    <collision>
      <origin
        xyz="0 0 0"
        rpy="0 0 0" />
      <geometry>
        <box size="0.000000001 0.0000001 0.000001"/>
      </geometry>
    </collision>
  </link>
  <joint
    name="Joint_19"
    type="prismatic">
    <origin
      xyz="3.5 -1.5 -0.2"
      rpy="0 0 0" />
    <parent
      link="base_link" />
    <child
      link="Link_19" />
    <axis
      xyz="-1 0 0" />
    <limit
      effort="100"
      lower="0"
      upper="4"
      velocity="10" />
  </joint>
  
	<!-- base_link -->
	<link name="base" />
	<joint name="base_link-base" type="fixed">
	<origin xyz="0 0 0" rpy="0 0 0"/>
	<parent link="base_link"/>
	<child link="base"/>
	</joint>

	<!-- flange frame -->
	<link name="flange"/>
	<joint type="fixed" name="joint_6-flange">
	<origin xyz="0 0 0" rpy="0 0 0"/>
	<parent link="Link_6"/>
	<child link="flange"/>
	<child link="Link_7"/>
	</joint>

	<!-- EF1_GR tool frame -->
	<link name="tool0" />
	<joint name="Link_6-tool0" type="fixed">
	<origin xyz="0.087264505 0.2964 -0.24" rpy="-3.1415927 0 0" />
	<parent link="flange" />
	<child link="tool0" />
	</joint>

	<!-- EF1_SC tool frame -->
	<link name="tool1" />
	<joint name="Link_6-tool1" type="fixed">
	<origin xyz="0.502065 0.43505 -0.176663" rpy="-1.57079632679 0.0 -1.57079632679" />
	<parent link="flange" />
	<child link="tool1" />
	</joint>

	<!-- EF1_NG tool frame -->
	<link name="tool2" />
	<joint name="flange-tool2" type="fixed">
	<origin xyz="0.400 -0.327 0.0" rpy="-1.57079632679 0 -1.57079632679" />
	<parent link="flange" />
	<child link="tool2" />
	</joint>

	<!-- EF1_NG2 tool frame -->
	<link name="tool3" />
	<joint name="Link_6-tool3" type="fixed">
	<origin xyz="0.226962 -0.705 0.002537" rpy="-1.57079632679 0.174533 0" />
	<parent link="flange" />
	<child link="tool3" />
	</joint>

	<!-- flange2 frame -->
	<link name="flange2"/>
	<joint type="fixed" name="joint_15-flange2">
	<origin xyz="0 0 0" rpy="0 0 0"/>
	<parent link="Link_15"/>
	<child link="flange2"/>
	<child link="Link_16"/>
	</joint>

	<!-- EF2_GR tool frame -->
	<link name="tool4" />
	<joint name="Link_15-tool4" type="fixed">
	<origin xyz="0.618323344138 0.455185395 -0.05935" rpy="0 -1.57079632679 0" />
	<parent link="flange2" />
	<child link="tool4" />
	</joint>

	<!-- EF2_NG1 tool frame -->
	<link name="tool5" />
	<joint name="Link_15-tool5" type="fixed">
	<origin xyz="0.352827674 -0.31656238 0.0519" rpy="0 -1.57079632679 0" />
	<parent link="flange2" />
	<child link="tool5" />
	</joint>

	<!-- EF2_NG2 tool frame -->
	<link name="tool6" />
	<joint name="Link_15-tool6" type="fixed">
	<origin xyz="0.276794723 -0.718262096 0.05165" rpy="1.57079632679 0 3.14159265359" />
	<parent link="flange2" />
	<child link="tool6" />
	</joint>
</robot>
